link:
library/asyncio-task.html#asyncio.Task.cancelled

docs:

<dt id="asyncio.Task.cancelled">
<code class="descname">cancelled</code><span class="sig-paren">(</span><span class="sig-paren">)</span><a class="headerlink" href="#asyncio.Task.cancelled" title="Permalink to this definition">Â¶</a></dt>
<dd><p>Return <code class="docutils literal notranslate"><span class="pre">True</span></code> if the Task is <em>cancelled</em>.</p>
<p>The Task is <em>cancelled</em> when the cancellation was requested with
<a class="reference internal" href="#asyncio.Task.cancel" title="asyncio.Task.cancel"><code class="xref py py-meth docutils literal notranslate"><span class="pre">cancel()</span></code></a> and the wrapped coroutine propagated the
<a class="reference internal" href="asyncio-exceptions.html#asyncio.CancelledError" title="asyncio.CancelledError"><code class="xref py py-exc docutils literal notranslate"><span class="pre">CancelledError</span></code></a> exception thrown into it.</p>
</dd>